<?xml version="1.0" encoding="UTF-8"?>
<testExecutions version="1">
    <file path="/home/vagrant/UE3DW24_S1/tests/user.test.js">
        <testCase name="Test : Get all users responds with json" duration="154"/>
        <testCase name="Test : cannot get one user responds with json" duration="18">
            <failure message="Error: expected 404 &quot;Not Found&quot;, got 200 &quot;OK&quot;"><![CDATA[Error: expected 404 "Not Found", got 200 "OK"
    at Object.<anonymous> (/home/vagrant/UE3DW24_S1/tests/user.test.js:20:10)
    at Promise.then.completed (/home/vagrant/UE3DW24_S1/node_modules/jest-circus/build/utils.js:380:26)
    at new Promise (<anonymous>)
    at callAsyncCircusFn (/home/vagrant/UE3DW24_S1/node_modules/jest-circus/build/utils.js:315:10)
    at _callCircusTest (/home/vagrant/UE3DW24_S1/node_modules/jest-circus/build/run.js:218:40)
    at processTicksAndRejections (internal/process/task_queues.js:95:5)
    at _runTest (/home/vagrant/UE3DW24_S1/node_modules/jest-circus/build/run.js:155:3)
    at _runTestsForDescribeBlock (/home/vagrant/UE3DW24_S1/node_modules/jest-circus/build/run.js:66:9)
----
    at Test.Object.<anonymous>.Test._assertStatus (/home/vagrant/UE3DW24_S1/node_modules/supertest/lib/test.js:304:12)
    at /home/vagrant/UE3DW24_S1/node_modules/supertest/lib/test.js:80:15
    at Test.Object.<anonymous>.Test._assertFunction (/home/vagrant/UE3DW24_S1/node_modules/supertest/lib/test.js:338:11)
    at Test.Object.<anonymous>.Test.assert (/home/vagrant/UE3DW24_S1/node_modules/supertest/lib/test.js:209:21)
    at Server.localAssert (/home/vagrant/UE3DW24_S1/node_modules/supertest/lib/test.js:167:12)
    at Object.onceWrapper (events.js:519:28)
    at Server.emit (events.js:400:28)
    at emitCloseNT (net.js:1677:8)
    at processTicksAndRejections (internal/process/task_queues.js:81:21)]]></failure>
        </testCase>
        <testCase name="Test : get one user responds with json" duration="11"/>
    </file>
</testExecutions>